{
 "cells": [
  {
   "cell_type": "markdown",
   "metadata": {},
   "source": [
    "# Notebook de testes"
   ]
  },
  {
   "cell_type": "code",
   "execution_count": 2,
   "metadata": {},
   "outputs": [
    {
     "ename": "ModuleNotFoundError",
     "evalue": "No module named 'findspark'",
     "output_type": "error",
     "traceback": [
      "\u001b[0;31m---------------------------------------------------------------------------\u001b[0m",
      "\u001b[0;31mModuleNotFoundError\u001b[0m                       Traceback (most recent call last)",
      "\u001b[1;32m/mnt/c/Users/davi.nascimento/Documents/siena_eeg_ecg/notebooks/teste.ipynb Cell 2'\u001b[0m in \u001b[0;36m<cell line: 1>\u001b[0;34m()\u001b[0m\n\u001b[0;32m----> <a href='vscode-notebook-cell://wsl%2Bubuntu-20.04/mnt/c/Users/davi.nascimento/Documents/siena_eeg_ecg/notebooks/teste.ipynb#ch0000001vscode-remote?line=0'>1</a>\u001b[0m \u001b[39mimport\u001b[39;00m \u001b[39mfindspark\u001b[39;00m\n\u001b[1;32m      <a href='vscode-notebook-cell://wsl%2Bubuntu-20.04/mnt/c/Users/davi.nascimento/Documents/siena_eeg_ecg/notebooks/teste.ipynb#ch0000001vscode-remote?line=2'>3</a>\u001b[0m findspark\u001b[39m.\u001b[39minit()\n",
      "\u001b[0;31mModuleNotFoundError\u001b[0m: No module named 'findspark'"
     ]
    }
   ],
   "source": [
    "import findspark\n",
    "\n",
    "findspark.init()"
   ]
  },
  {
   "cell_type": "code",
   "execution_count": 3,
   "metadata": {},
   "outputs": [
    {
     "name": "stdout",
     "output_type": "stream",
     "text": [
      "\u001b[33mWARNING: Retrying (Retry(total=4, connect=None, read=None, redirect=None, status=None)) after connection broken by 'SSLError(SSLCertVerificationError(1, '[SSL: CERTIFICATE_VERIFY_FAILED] certificate verify failed: self signed certificate in certificate chain (_ssl.c:1129)'))': /simple/findspark/\u001b[0m\u001b[33m\n",
      "\u001b[0m\u001b[33mWARNING: Retrying (Retry(total=3, connect=None, read=None, redirect=None, status=None)) after connection broken by 'SSLError(SSLCertVerificationError(1, '[SSL: CERTIFICATE_VERIFY_FAILED] certificate verify failed: self signed certificate in certificate chain (_ssl.c:1129)'))': /simple/findspark/\u001b[0m\u001b[33m\n",
      "\u001b[0m\u001b[33mWARNING: Retrying (Retry(total=2, connect=None, read=None, redirect=None, status=None)) after connection broken by 'SSLError(SSLCertVerificationError(1, '[SSL: CERTIFICATE_VERIFY_FAILED] certificate verify failed: self signed certificate in certificate chain (_ssl.c:1129)'))': /simple/findspark/\u001b[0m\u001b[33m\n",
      "\u001b[0m\u001b[33mWARNING: Retrying (Retry(total=1, connect=None, read=None, redirect=None, status=None)) after connection broken by 'SSLError(SSLCertVerificationError(1, '[SSL: CERTIFICATE_VERIFY_FAILED] certificate verify failed: self signed certificate in certificate chain (_ssl.c:1129)'))': /simple/findspark/\u001b[0m\u001b[33m\n",
      "\u001b[0m\u001b[33mWARNING: Retrying (Retry(total=0, connect=None, read=None, redirect=None, status=None)) after connection broken by 'SSLError(SSLCertVerificationError(1, '[SSL: CERTIFICATE_VERIFY_FAILED] certificate verify failed: self signed certificate in certificate chain (_ssl.c:1129)'))': /simple/findspark/\u001b[0m\u001b[33m\n",
      "\u001b[0mCould not fetch URL https://pypi.org/simple/findspark/: There was a problem confirming the ssl certificate: HTTPSConnectionPool(host='pypi.org', port=443): Max retries exceeded with url: /simple/findspark/ (Caused by SSLError(SSLCertVerificationError(1, '[SSL: CERTIFICATE_VERIFY_FAILED] certificate verify failed: self signed certificate in certificate chain (_ssl.c:1129)'))) - skipping\n",
      "\u001b[31mERROR: Could not find a version that satisfies the requirement findspark (from versions: none)\u001b[0m\u001b[31m\n",
      "\u001b[0m\u001b[31mERROR: No matching distribution found for findspark\u001b[0m\u001b[31m\n",
      "\u001b[0m"
     ]
    }
   ],
   "source": [
    "!pip install findspark"
   ]
  },
  {
   "cell_type": "code",
   "execution_count": null,
   "metadata": {},
   "outputs": [],
   "source": []
  },
  {
   "cell_type": "code",
   "execution_count": 5,
   "metadata": {},
   "outputs": [
    {
     "name": "stdout",
     "output_type": "stream",
     "text": [
      "\u001b[33mWARNING: Disabling all use of wheels due to the use of --build-option / --global-option / --install-option.\u001b[0m\u001b[33m\n",
      "\u001b[0m\u001b[33mWARNING: Retrying (Retry(total=4, connect=None, read=None, redirect=None, status=None)) after connection broken by 'SSLError(SSLCertVerificationError(1, '[SSL: CERTIFICATE_VERIFY_FAILED] certificate verify failed: self signed certificate in certificate chain (_ssl.c:1129)'))': /simple/gensim/\u001b[0m\u001b[33m\n",
      "\u001b[0m\u001b[33mWARNING: Retrying (Retry(total=3, connect=None, read=None, redirect=None, status=None)) after connection broken by 'SSLError(SSLCertVerificationError(1, '[SSL: CERTIFICATE_VERIFY_FAILED] certificate verify failed: self signed certificate in certificate chain (_ssl.c:1129)'))': /simple/gensim/\u001b[0m\u001b[33m\n",
      "\u001b[0m\u001b[33mWARNING: Retrying (Retry(total=2, connect=None, read=None, redirect=None, status=None)) after connection broken by 'SSLError(SSLCertVerificationError(1, '[SSL: CERTIFICATE_VERIFY_FAILED] certificate verify failed: self signed certificate in certificate chain (_ssl.c:1129)'))': /simple/gensim/\u001b[0m\u001b[33m\n",
      "\u001b[0m\u001b[33mWARNING: Retrying (Retry(total=1, connect=None, read=None, redirect=None, status=None)) after connection broken by 'SSLError(SSLCertVerificationError(1, '[SSL: CERTIFICATE_VERIFY_FAILED] certificate verify failed: self signed certificate in certificate chain (_ssl.c:1129)'))': /simple/gensim/\u001b[0m\u001b[33m\n",
      "\u001b[0m\u001b[33mWARNING: Retrying (Retry(total=0, connect=None, read=None, redirect=None, status=None)) after connection broken by 'SSLError(SSLCertVerificationError(1, '[SSL: CERTIFICATE_VERIFY_FAILED] certificate verify failed: self signed certificate in certificate chain (_ssl.c:1129)'))': /simple/gensim/\u001b[0m\u001b[33m\n",
      "\u001b[0mCould not fetch URL https://pypi.org/simple/gensim/: There was a problem confirming the ssl certificate: HTTPSConnectionPool(host='pypi.org', port=443): Max retries exceeded with url: /simple/gensim/ (Caused by SSLError(SSLCertVerificationError(1, '[SSL: CERTIFICATE_VERIFY_FAILED] certificate verify failed: self signed certificate in certificate chain (_ssl.c:1129)'))) - skipping\n",
      "\u001b[31mERROR: Could not find a version that satisfies the requirement gensim (from versions: none)\u001b[0m\u001b[31m\n",
      "\u001b[0m\u001b[31mERROR: No matching distribution found for gensim\u001b[0m\u001b[31m\n",
      "\u001b[0m"
     ]
    }
   ],
   "source": [
    "!pip install gensim config --global http.sslVerify false\n"
   ]
  },
  {
   "cell_type": "code",
   "execution_count": 7,
   "metadata": {},
   "outputs": [
    {
     "name": "stdout",
     "output_type": "stream",
     "text": [
      "Requirement already satisfied: pip in /home/davi/miniconda3/envs/siena_eeg_ecg/lib/python3.9/site-packages (22.0.4)\n"
     ]
    }
   ],
   "source": [
    "!python -m pip install --trusted-host pypi.python.org --trusted-host files.pythonhosted.org --trusted-host pypi.org --upgrade pip"
   ]
  },
  {
   "cell_type": "code",
   "execution_count": 5,
   "metadata": {},
   "outputs": [],
   "source": [
    "!pip freeze > /mnt/c/Users/davi.nascimento/Documents/siena_eeg_ecg/requirements.txt"
   ]
  },
  {
   "cell_type": "code",
   "execution_count": 4,
   "metadata": {},
   "outputs": [
    {
     "name": "stdout",
     "output_type": "stream",
     "text": [
      "Processing /mnt/c/Users/davi.nascimento/Downloads/mne-0.24.1-py3-none-any.whl\n",
      "\u001b[33mWARNING: Retrying (Retry(total=4, connect=None, read=None, redirect=None, status=None)) after connection broken by 'SSLError(SSLCertVerificationError(1, '[SSL: CERTIFICATE_VERIFY_FAILED] certificate verify failed: self signed certificate in certificate chain (_ssl.c:1129)'))': /simple/numpy/\u001b[0m\u001b[33m\n",
      "\u001b[0m\u001b[33mWARNING: Retrying (Retry(total=3, connect=None, read=None, redirect=None, status=None)) after connection broken by 'SSLError(SSLCertVerificationError(1, '[SSL: CERTIFICATE_VERIFY_FAILED] certificate verify failed: self signed certificate in certificate chain (_ssl.c:1129)'))': /simple/numpy/\u001b[0m\u001b[33m\n",
      "\u001b[0m\u001b[33mWARNING: Retrying (Retry(total=2, connect=None, read=None, redirect=None, status=None)) after connection broken by 'SSLError(SSLCertVerificationError(1, '[SSL: CERTIFICATE_VERIFY_FAILED] certificate verify failed: self signed certificate in certificate chain (_ssl.c:1129)'))': /simple/numpy/\u001b[0m\u001b[33m\n",
      "\u001b[0m\u001b[33mWARNING: Retrying (Retry(total=1, connect=None, read=None, redirect=None, status=None)) after connection broken by 'SSLError(SSLCertVerificationError(1, '[SSL: CERTIFICATE_VERIFY_FAILED] certificate verify failed: self signed certificate in certificate chain (_ssl.c:1129)'))': /simple/numpy/\u001b[0m\u001b[33m\n",
      "\u001b[0m\u001b[33mWARNING: Retrying (Retry(total=0, connect=None, read=None, redirect=None, status=None)) after connection broken by 'SSLError(SSLCertVerificationError(1, '[SSL: CERTIFICATE_VERIFY_FAILED] certificate verify failed: self signed certificate in certificate chain (_ssl.c:1129)'))': /simple/numpy/\u001b[0m\u001b[33m\n",
      "\u001b[0mCould not fetch URL https://pypi.org/simple/numpy/: There was a problem confirming the ssl certificate: HTTPSConnectionPool(host='pypi.org', port=443): Max retries exceeded with url: /simple/numpy/ (Caused by SSLError(SSLCertVerificationError(1, '[SSL: CERTIFICATE_VERIFY_FAILED] certificate verify failed: self signed certificate in certificate chain (_ssl.c:1129)'))) - skipping\n",
      "\u001b[31mERROR: Could not find a version that satisfies the requirement numpy>=1.15.4 (from mne) (from versions: none)\u001b[0m\u001b[31m\n",
      "\u001b[0m\u001b[31mERROR: No matching distribution found for numpy>=1.15.4\u001b[0m\u001b[31m\n",
      "\u001b[0m"
     ]
    }
   ],
   "source": [
    "\n",
    "!pip install /mnt/c/Users/davi.nascimento/Downloads/mne-0.24.1-py3-none-any.whl "
   ]
  }
 ],
 "metadata": {
  "interpreter": {
   "hash": "676d897f427d94a86f2cc2ce6d393a432491b28b1655c15eb47ad7d90dd20eb2"
  },
  "kernelspec": {
   "display_name": "Python 3.9.5 ('siena_eeg_ecg')",
   "language": "python",
   "name": "python3"
  },
  "language_info": {
   "codemirror_mode": {
    "name": "ipython",
    "version": 3
   },
   "file_extension": ".py",
   "mimetype": "text/x-python",
   "name": "python",
   "nbconvert_exporter": "python",
   "pygments_lexer": "ipython3",
   "version": "3.9.5"
  },
  "orig_nbformat": 4
 },
 "nbformat": 4,
 "nbformat_minor": 2
}
